Workbook

Sheet Raw Data
A1: Code | B1: Governance Units | C1: Provinces | D1: Districts | E1: Name of Government Unit | F1: Children Immunized-BCG Doses | G1: Children Immunized-DPT-HepB-Hib-1st | H1: Children Immunized-DPT-HepB-Hib-3rd | I1: Children Immunized-OPV-3rd | J1: Children Immunized-PCV-3rd | K1: Children Immunized-Measles/Rubella-12-23 Months | L1: Children Immunized-JE | M1: Pregnant women Immunized-TD(Pregnant Women)-2 | N1: Pregnant women Immunized-TD(Pregnant Women)-2+ | O1: Fully Immunized Children | P1: Health Facilities within Catchment Area-Immunization Sessions-Planned | Q1: Health Facilities within Catchment Area-Immunization Sessions-Planned/months | R1: Health Facilities within Catchment Area-Immunization Sessions-Conducted | S1: Safe Motherhood Program--Birth Weight-Low and Very low (< 2.5 kg) | T1: Registered for GM-New Visit 0-11 Months - Normal | U1: Registered for GM-New Visit 0-11 Months - Moderate | V1: Registered for GM-New Visit 0-11 Months - Severe | W1: Registered for GM-New Visit 12-23 Months - Normal | X1: Registered for GM-New Visit 12-23 Months - Moderate | Y1: Registered for GM-New Visit 12-23 Months - Severe | Z1: < 5yr Children Receiving-Vitamin A-6-59 Months (sharwan-Poush 2074) | AA1: Nutrition-< 5yr Children Receiving-Deworming Tab (Sharwan-poush 2074) | AB1: CBIMCI-(2-59Months)-Classification-Diarrhoea-No Dehydration | AC1: CBIMCI-(2-59Months)-Classification-Diarrhoea-Some Dehydration | AD1: CBIMCI-(2-59Months)-Classification-Diarrhoea-Severe Dehydration | AE1: FCHV Program-CBIMCI-(2-59)Months-Total Diarrhoea Cases | AF1: CBIMCI-(2-59Months)-Treatment-ORS & Zinc | AG1: FCHV Program-CBIMCI-(2-59)Months-Treated with ORS & Zinc | AH1: Total Diarrhoea cases | AI1: Total diarrhoea treated with ORS and zinc | AJ1: CBIMCI-(2-59Months)-Classification-ARI-No Pneumonia | AK1: CBIMCI-(2-59Months)-Classification-ARI-Pneumonia | AL1: CBIMCI-(2-59Months)-Classification-ARI-Severe Pneu/Very Severe Disease | AM1: FCHV Program-CBIMCI-(2-59)Months-Total cases ARI | AN1: Total ARI cases | AO1: Total Pneumonia cases (at HF & Outreach) | AP1: CBIMCI-(2-59Months)-Treatment-Amoxicillin | AQ1: CBIMCI-(2-59Months)-Treatment-Cotrim Paediatrics | AR1: CBIMCI-(2-59Months)-Treatment-Other Antibiotics Facility | AS1: Safe Motherhood Program-Antenatal Checkup-First ANC Visit (any time)< 20 Years | AT1: Safe Motherhood Program-Antenatal Checkup-First ANC Visit (any time)≥ 20 Years | AU1: Safe Motherhood Program-Antenatal Checkup-Four ANC Visits as per Protocol< 20 Years | AV1: Safe Motherhood Program-Antenatal Checkup-Four ANC Visits as per Protocol≥ 20 Years | AW1: Nutrition-Pregnant Women Receiving-180 Iron Tablets | AX1: Safe Motherhood Program-Delivery Service-Non-SBA Health Workers Facility | AY1: Safe Motherhood Program-Delivery Service-Non-SBA Health Workers Home | AZ1: Safe Motherhood Program-Delivery Service-Skilled Birth Attendants (SBA)Facility | BA1: Safe Motherhood Program-Delivery Service-Skilled Birth Attendants (SBA)Home | BB1: Safe Motherhood Program-3 PNC Visits as per Protocol | BC1: FCHV Program-Maternal Death-Antepartum | BD1: FCHV Program-Maternal Death-Intrapartum | BE1: FCHV Program-Maternal Death-Postpartum | BF1: Safe Motherhood Program-Maternal Death-Antepartum | BG1: Safe Motherhood Program-Maternal Death-Intrapartum | BH1: Safe Motherhood Program-Maternal Death-Postpartum | BI1: Safe Motherhood Program-Safe Abortion Service-Number of Women < 20 Years-Medical | BJ1: Safe Motherhood Program-Safe Abortion Service-Number of Women < 20 Years-Surgical | BK1: Safe Motherhood Program-Safe Abortion Service-Number of Women ≥ 20 Years-Medical | BL1: Safe Motherhood Program-Safe Abortion Service-Number of Women ≥ 20 Years-Surgical | BM1: CBIMCI <2Months-Total Death <=28 Days, Facility | BN1: CBIMCI <2Months-Total Death <=28 Days, OutReach Clinics | BO1: FCHV Program-Death-≤28 days | BP1: Safe Motherhood Program-Maternal Death-Neonatal death at Health Facility | BQ1: Total number of neonatal deaths | BR1: Family Planning Program-Temporary FP Method-Pills-Current User | BS1: Family Planning Program-Temporary FP Method-Implant-Current User | BT1: Family Planning Program-Temporary FP Method-IUCD-Current User | BU1: Family Planning Program-Temporary FP Method-Depo-Current User | BV1: Family Planning Program-Temporary FP Method-Condom-Pieces Qty/150 | BW1: Family Planning Program-Postpartum FP Acceptors (Within 48 Hours of Delivery)-IUCD | BX1: Family Planning Program-Postpartum FP Acceptors (Within 48 Hours of Delivery)-Implant | BY1: Family Planning Program-Postpartum FP Acceptors (Within 48 Hours of Delivery)-Tubectomy | BZ1: Total FCHVs within Catchment Area | CA1: FCHV Program-SMH/FP-Meetings Held of Mothers Group | CB1: Health Facilities within Catchment Area-Outreach Clinics-Planned/months | CC1: Health Facilities within Catchment Area-Outreach Clinics-Conducted | CD1: HIV Tested in HTC Program | CE1: HIV found Positive in HTC Program | CF1: Outpatient Morbidity-Communicable-Vector Borne-Filariasis Cases | CG1: Outpatient Morbidity-Trachoma Cases | CH1: No. of new TB cases registered | CI1: TB PBC (new) registered cases | CJ1: TB PBC (new) treatment completed (cured and completed) cases | CK1: Malaria- Total number of positive cases | CL1: Number of P. Falciparum (PF) cases | CM1: Malaria- Diagnosis & Result Examined | CN1: Malaria- Blood Slide Collection | CO1: Leprosy-Total Additions-New Cases Never Registered earlier-Multi Bacillary | CP1: Leprosy-Total Additions-New Cases Never registered earlier-Pauci Bacillary | CQ1: Leprosy Patient (from OPD) | CR1: Total New OPD Visits Female | CS1: Total New OPD Visits Male
A2: 1 | B2: Province | C2: Province 1 | D2: Province | E2: Province 1 | F2: 95215 | G2: 91247 | H2: 87066 | I2: 87123 | J2: 87192 | K2: 70206 | L2: 81284 | M2: 52313 | N2: 22415 | O2: 84239 | P2: =Q2*12 -> 30993 | Q2: 2582.75 | R2: 29327 | S2: 6832 | T2: 84790 | U2: 1245 | V2: 428 | W2: 49530 | X2: 1316 | Y2: 458 | Z2: 391379 | AA2: 350486 | AB2: 41201 | AC2: 10397 | AD2: 194 | AE2: 128468 | AF2: 49104 | AG2: 112690 | AH2: =AB2+AC2+AD2+AE2 -> 180260 | AI2: =AF2+AG2 -> 161794 | AJ2: 110881 | AK2: 33133 | AL2: 805 | AM2: 184329 | AN2: =AJ2+AK2+AL2+AM2 -> 329148 | AO2: =AK2+AL2 -> 33938 | AP2: 31114 | AQ2: 13637 | AR2: 13867 | AS2: 22666 | AT2: 91874 | AU2: 8886 | AV2: 42156 | AW2: 40720 | AX2: 1218 | AY2: 867 | AZ2: 56193 | BA2: 360 | BB2: 12935 | BC2: 4 | BD2: 9 | BE2: 7 | BF2: 0 | BG2: 5 | BH2: 16 | BI2: 987 | BJ2: 374 | BK2: 10421 | BL2: 4072 | BM2: 11 | BN2: 1 | BO2: 310 | BP2: 189 | BQ2: =BM2+BN2+BO2+BP2 -> 511 | BR2: 38510 | BS2: 55508 | BT2: 23655 | BU2: 77287 | BV2: 22652.293 | BW2: 862 | BX2: 72 | BY2: 720 | BZ2: 8662.6667 | CA2: 87679 | CB2: 2217.8333 | CC2: 24732 | CD2: 14714 | CE2: 142 | CF2: 103 | CG2: 734 | CH2: 3587 | CI2: 1720 | CJ2: 1524 | CK2: 24 | CL2: 5 | CM2: 16074 | CN2: 16061 | CO2: 213 | CP2: 154 | CQ2: ='Top Ten Disease (OPD)'!FC3 -> 401 | CR2: 2050400 | CS2: 1620167
A3: 101 | B3: District | C3: Province 1 | D3: Taplejung | E3: TAPLEJUNG | F3: 2611 | G3: 2559 | H3: 2398 | I3: 2423 | J3: 2289 | K3: 1949 | L3: 2570 | M3: 1432 | N3: 582 | O3: 1901 | P3: =Q3*12 -> 1636 | Q3: 136.33333 | R3: 1455 | S3: 27 | T3: 2793 | U3: 86 | V3: 7 | W3: 973 | X3: 36 | Y3: 1 | Z3: 10058 | AA3: 8964 | AB3: 2033 | AC3: 726 | AD3: 11 | AE3: 4351 | AF3: 2557 | AG3: 4148 | AH3: =AB3+AC3+AD3+AE3 -> 7121 | AI3: =AF3+AG3 -> 6705 | AJ3: 5394 | AK3: 1369 | AL3: 25 | AM3: 5119 | AN3: =AJ3+AK3+AL3+AM3 -> 11907 | AO3: =AK3+AL3 -> 1394 | AP3: 1090 | AQ3: 208 | AR3: 99 | AS3: 594 | AT3: 1793 | AU3: 170 | AV3: 748 | AW3: 1031 | AX3: 49 | AY3: 136 | AZ3: 1099 | BA3: 10 | BB3: 472 | BC3: 0 | BD3: 1 | BE3: 3 | BF3: 0 | BG3: 0 | BH3: 1 | BI3: 18 | BJ3: 22 | BK3: 172 | BL3: 284 | BM3: 0 | BN3: 0 | BO3: 42 | BP3: 3 | BQ3: =BM3+BN3+BO3+BP3 -> 45 | BR3: 715 | BS3: 1884 | BT3: 452 | BU3: 2332 | BV3: 1147.6133 | BW3: 1 | BX3: 1 | BY3: 1 | BZ3: 872.41667 | CA3: 5725 | CB3: 178.91667 | CC3: 1962 | CD3: 0 | CE3: 0 | CF3: 0 | CG3: 73 | CH3: 54 | CI3: 27 | CJ3: 18 | CK3: 0 | CL3: 0 | CM3: 600 | CN3: 600 | CO3: 0 | CP3: 0 | CQ3: ='Top Ten Disease (OPD)'!FC4 -> 0 | CR3: 59515 | CS3: 52433
A4: 10101 | B4: Rural Municipality | C4: Province 1 | D4: Taplejung | E4: Phaktanlung Rural Municipality | F4: 282 | G4: 297 | H4: 283 | I4: 280 | J4: 261 | K4: 178 | L4: 383 | M4: 146 | N4: 72 | O4: 220 | P4: =Q4*12 -> 206 | Q4: 17.166667 | R4: 161 | S4: 0 | T4: 300 | U4: 0 | V4: 0 | W4: 84 | X4: 5 | Y4: 0 | Z4: 1037 | AA4: 844 | AB4: 318 | AC4: 98 | AD4: 0 | AE4: 478 | AF4: 382 | AG4: 434 | AH4: =AB4+AC4+AD4+AE4 -> 894 | AI4: =AF4+AG4 -> 816 | AJ4: 682 | AK4: 256 | AL4: 6 | AM4: 535 | AN4: =AJ4+AK4+AL4+AM4 -> 1479 | AO4: =AK4+AL4 -> 262 | AP4: 200 | AQ4: 63 | AR4: 9 | AS4: 69 | AT4: 143 | AU4: 22 | AV4: 77 | AW4: 109 | AX4: 16 | AY4: 1 | AZ4: 72 | BA4: 0 | BB4: 40 | BC4: 0 | BD4: 0 | BE4: 0 | BF4: 0 | BG4: 0 | BH4: 0 | BI4: 0 | BJ4: 0 | BK4: 0 | BL4: 0 | BM4: 0 | BN4: 0 | BO4: 5 | BP4: 0 | BQ4: =BM4+BN4+BO4+BP4 -> 5 | BR4: 94 | BS4: 209 | BT4: 36 | BU4: 311 | BV4: 104.73333 | BW4: 0 | BX4: 0 | BY4: 0 | BZ4: 111 | CA4: 789 | CB4: 25.083333 | CC4: 276 | CD4: 0 | CE4: 0 | CF4: 0 | CG4: 3 | CH4: 3 | CI4: 2 | CJ4: 0 | CK4: 0 | CL4: 0 | CM4: 0 | CN4: 0 | CO4: 0 | CP4: 0 | CQ4: ='Top Ten Disease (OPD)'!FC5 -> 0 | CR4: 5777 | CS4: 5397
A5: 10102 | B5: Rural Municipality | C5: Province 1 | D5: Taplejung | E5: Mikwakhola Rural Municipality | F5: 177 | G5: 193 | H5: 191 | I5: 194 | J5: 187 | K5: 138 | L5: 173 | M5: 56 | N5: 33 | O5: 146 | P5: =Q5*12 -> 128.72727 | Q5: 10.727273 | R5: 115 | S5: 2 | T5: 199 | U5: 5 | V5: 1 | W5: 68 | X5: 1 | Y5: 0 | Z5: 748 | AA5: 675 | AB5: 198 | AC5: 34 | AD5: 0 | AE5: 524 | AF5: 236 | AG5: 447 | AH5: =AB5+AC5+AD5+AE5 -> 756 | AI5: =AF5+AG5 -> 683 | AJ5: 310 | AK5: 51 | AL5: 0 | AM5: 576 | AN5: =AJ5+AK5+AL5+AM5 -> 937 | AO5: =AK5+AL5 -> 51 | AP5: 38 | AQ5: 8 | AR5: 3 | AS5: 35 | AT5: 127 | AU5: 14 | AV5: 43 | AW5: 127 | AX5: 0 | AY5: 39 | AZ5: 37 | BA5: 0 | BB5: 41 | BC5: 0 | BD5: 1 | BE5: 1 | BF5: 0 | BG5: 0 | BH5: 0 | BI5: 0 | BJ5: 0 | BK5: 0 | BL5: 0 | BM5: 0 | BN5: 0 | BO5: 5 | BP5: 0 | BQ5: =BM5+BN5+BO5+BP5 -> 5 | BR5: 35 | BS5: 43 | BT5: 12 | BU5: 180 | BV5: 56.073333 | BW5: 0 | BX5: 0 | BY5: 0 | BZ5: 62.833333 | CA5: 172 | CB5: 14.416667 | CC5: 138 | CD5: 0 | CE5: 0 | CF5: 0 | CG5: 7 | CH5: 3 | CI5: 0 | CJ5: 0 | CK5: 0 | CL5: 0 | CM5: 0 | CN5: 0 | CO5: 0 | CP5: 0 | CQ5: ='Top Ten Disease (OPD)'!FC6 -> 0 | CR5: 2846 | CS5: 2626
A6: 10103 | B6: Rural Municipality | C6: Province 1 | D6: Taplejung | E6: Meringden Rural Municipality | F6: 252 | G6: 221 | H6: 215 | I6: 226 | J6: 209 | K6: 175 | L6: 205 | M6: 117 | N6: 55 | O6: 220 | P6: =Q6*12 -> 183 | Q6: 15.25 | R6: 174 | S6: 3 | T6: 278 | U6: 0 | V6: 0 | W6: 24 | X6: 1 | Y6: 0 | Z6: 1187 | AA6: 1049 | AB6: 227 | AC6: 82 | AD6: 0 | AE6: 364 | AF6: 291 | AG6: 382 | AH6: =AB6+AC6+AD6+AE6 -> 673 | AI6: =AF6+AG6 -> 673 | AJ6: 507 | AK6: 116 | AL6: 5 | AM6: 491 | AN6: =AJ6+AK6+AL6+AM6 -> 1119 | AO6: =AK6+AL6 -> 121 | AP6: 98 | AQ6: 9 | AR6: 3 | AS6: 50 | AT6: 195 | AU6: 14 | AV6: 53 | AW6: 70 | AX6: 10 | AY6: 9 | AZ6: 71 | BA6: 2 | BB6: 19 | BC6: 0 | BD6: 0 | BE6: 0 | BF6: 0 | BG6: 0 | BH6: 0 | BI6: 5 | BJ6: 5 | BK6: 5 | BL6: 5 | BM6: 0 | BN6: 0 | BO6: 3 | BP6: 1 | BQ6: =BM6+BN6+BO6+BP6 -> 4 | BR6: 87 | BS6: 179 | BT6: 107 | BU6: 285 | BV6: 63.82 | BW6: 0 | BX6: 0 | BY6: 0 | BZ6: 108.33333 | CA6: 676 | CB6: 17.583333 | CC6: 203 | CD6: 0 | CE6: 0 | CF6: 0 | CG6: 0 | CH6: 6 | CI6: 1 | CJ6: 0 | CK6: 0 | CL6: 0 | CM6: 0 | CN6: 0 | CO6: 0 | CP6: 0 | CQ6: ='Top Ten Disease (OPD)'!FC7 -> 0 | CR6: 4512 | CS6: 4462
A7: 10104 | B7: Rural Municipality | C7: Province 1 | D7: Taplejung | E7: Maiwakhola Rural Municipality | F7: 192 | G7: 194 | H7: 192 | I7: 200 | J7: 193 | K7: 134 | L7: 180 | M7: 84 | N7: 43 | O7: 178 | P7: =Q7*12 -> 102 | Q7: 8.5 | R7: 93 | S7: 0 | T7: 240 | U7: 1 | V7: 1 | W7: 173 | X7: 2 | Y7: 1 | Z7: 1283 | AA7: 1146 | AB7: 195 | AC7: 41 | AD7: 0 | AE7: 274 | AF7: 194 | AG7: 287 | AH7: =AB7+AC7+AD7+AE7 -> 510 | AI7: =AF7+AG7 -> 481 | AJ7: 492 | AK7: 69 | AL7: 0 | AM7: 350 | AN7: =AJ7+AK7+AL7+AM7 -> 911 | AO7: =AK7+AL7 -> 69 | AP7: 53 | AQ7: 3 | AR7: 42 | AS7: 36 | AT7: 164 | AU7: 6 | AV7: 53 | AW7: 49 | AX7: 3 | AY7: 5 | AZ7: 37 | BA7: 0 | BB7: 17 | BC7: 0 | BD7: 0 | BE7: 1 | BF7: 0 | BG7: 0 | BH7: 1 | BI7: 0 | BJ7: 0 | BK7: 9 | BL7: 0 | BM7: 0 | BN7: 0 | BO7: 9 | BP7: 0 | BQ7: =BM7+BN7+BO7+BP7 -> 9 | BR7: 43 | BS7: 126 | BT7: 38 | BU7: 116 | BV7: 62.033333 | BW7: 0 | BX7: 0 | BY7: 0 | BZ7: 66.833333 | CA7: 457 | CB7: 8.4166667 | CC7: 81 | CD7: 0 | CE7: 0 | CF7: 0 | CG7: 0 | CH7: 4 | CI7: 3 | CJ7: 0 | CK7: 0 | CL7: 0 | CM7: 0 | CN7: 0 | CO7: 0 | CP7: 0 | CQ7: ='Top Ten Disease (OPD)'!FC8 -> 0 | CR7: 3682 | CS7: 3087
A8: 10105 | B8: Rural Municipality | C8: Province 1 | D8: Taplejung | E8: Aatharai Tribeni Rural Municipality | F8: 278 | G8: 278 | H8: 271 | I8: 271 | J8: 236 | K8: 234 | L8: 249 | M8: 116 | N8: 107 | O8: 249 | P8: =Q8*12 -> 201 | Q8: 16.75 | R8: 188 | S8: 0 | T8: 415 | U8: 16 | V8: 1 | W8: 226 | X8: 16 | Y8: 0 | Z8: 1945 | AA8: 1819 | AB8: 304 | AC8: 72 | AD8: 0 | AE8: 410 | AF8: 378 | AG8: 382 | AH8: =AB8+AC8+AD8+AE8 -> 786 | AI8: =AF8+AG8 -> 760 | AJ8: 741 | AK8: 95 | AL8: 1 | AM8: 273 | AN8: =AJ8+AK8+AL8+AM8 -> 1110 | AO8: =AK8+AL8 -> 96 | AP8: 69 | AQ8: 20 | AR8: 5 | AS8: 70 | AT8: 174 | AU8: 34 | AV8: 121 | AW8: 153 | AX8: 12 | AY8: 13 | AZ8: 79 | BA8: 0 | BB8: 61 | BC8: 0 | BD8: 0 | BE8: 0 | BF8: 0 | BG8: 0 | BH8: 0 | BI8: 0 | BJ8: 0 | BK8: 0 | BL8: 0 | BM8: 0 | BN8: 0 | BO8: 2 | BP8: 0 | BQ8: =BM8+BN8+BO8+BP8 -> 2 | BR8: 97 | BS8: 217 | BT8: 50 | BU8: 297 | BV8: 81.566667 | BW8: 0 | BX8: 0 | BY8: 0 | BZ8: 71.5 | CA8: 330 | CB8: 15 | CC8: 175 | CD8: 0 | CE8: 0 | CF8: 0 | CG8: 2 | CH8: 6 | CI8: 0 | CJ8: 0 | CK8: 0 | CL8: 0 | CM8: 0 | CN8: 0 | CO8: 0 | CP8: 0 | CQ8: ='Top Ten Disease (OPD)'!FC9 -> 0 | CR8: 6499 | CS8: 5771
A9: 10106 | B9: Municipality | C9: Province 1 | D9: Taplejung | E9: Phungling Municipality | F9: 722 | G9: 623 | H9: 548 | I9: 539 | J9: 529 | K9: 478 | L9: 605 | M9: 520 | N9: 74 | O9: 210 | P9: =Q9*12 -> 203 | Q9: 16.916667 | R9: 163 | S9: 17 | T9: 491 | U9: 40 | V9: 2 | W9: 50 | X9: 4 | Y9: 0 | Z9: 481 | AA9: 434 | AB9: 271 | AC9: 156 | AD9: 0 | AE9: 1055 | AF9: 304 | AG9: 782 | AH9: =AB9+AC9+AD9+AE9 -> 1482 | AI9: =AF9+AG9 -> 1086 | AJ9: 607 | AK9: 160 | AL9: 0 | AM9: 1024 | AN9: =AJ9+AK9+AL9+AM9 -> 1791 | AO9: =AK9+AL9 -> 160 | AP9: 107 | AQ9: 37 | AR9: 6 | AS9: 125 | AT9: 522 | AU9: 29 | AV9: 183 | AW9: 197 | AX9: 0 | AY9: 0 | AZ9: 718 | BA9: 0 | BB9: 240 | BC9: 0 | BD9: 0 | BE9: 0 | BF9: 0 | BG9: 0 | BH9: 0 | BI9: 13 | BJ9: 17 | BK9: 156 | BL9: 279 | BM9: 0 | BN9: 0 | BO9: 3 | BP9: 2 | BQ9: =BM9+BN9+BO9+BP9 -> 5 | BR9: 62 | BS9: 466 | BT9: 45 | BU9: 421 | BV9: 612.37333 | BW9: 0 | BX9: 0 | BY9: 1 | BZ9: 100.16667 | CA9: 673 | CB9: 20 | CC9: 197 | CD9: 0 | CE9: 0 | CF9: 0 | CG9: 59 | CH9: 25 | CI9: 18 | CJ9: 18 | CK9: 0 | CL9: 0 | CM9: 0 | CN9: 0 | CO9: 0 | CP9: 0 | CQ9: ='Top Ten Disease (OPD)'!FC10 -> 0 | CR9: 19182 | CS9: 16347
A10: 10107 | B10: Rural Municipality | C10: Province 1 | D10: Taplejung | E10: Yangwarak Rural Municipality | F10: 260 | G10: 268 | H10: 241 | I10: 244 | J10: 223 | K10: 203 | L10: 263 | M10: 143 | N10: 67 | O10: 229 | P10: =Q10*12 -> 201 | Q10: 16.75 | R10: 192 | S10: 1 | T10: 342 | U10: 0 | V10: 0 | W10: 132 | X10: 0 | Y10: 0 | Z10: 1118 | AA10: 1006 | AB10: 213 | AC10: 52 | AD10: 0 | AE10: 630 | AF10: 297 | AG10: 834 | AH10: =AB10+AC10+AD10+AE10 -> 895 | AI10: =AF10+AG10 -> 1131 | AJ10: 730 | AK10: 251 | AL10: 0 | AM10: 527 | AN10: =AJ10+AK10+AL10+AM10 -> 1508 | AO10: =AK10+AL10 -> 251 | AP10: 208 | AQ10: 20 | AR10: 2 | AS10: 65 | AT10: 160 | AU10: 16 | AV10: 76 | AW10: 107 | AX10: 2 | AY10: 1 | AZ10: 35 | BA10: 2 | BB10: 16 | BC10: 0 | BD10: 0 | BE10: 1 | BF10: 0 | BG10: 0 | BH10: 0 | BI10: 0 | BJ10: 0 | BK10: 0 | BL10: 0 | BM10: 0 | BN10: 0 | BO10: 5 | BP10: 0 | BQ10: =BM10+BN10+BO10+BP10 -> 5 | BR10: 41 | BS10: 227 | BT10: 18 | BU10: 139 | BV10: 55.073333 | BW10: 0 | BX10: 1 | BY10: 0 | BZ10: 95.25 | CA10: 580 | CB10: 23.916667 | CC10: 282 | CD10: 0 | CE10: 0 | CF10: 0 | CG10: 1 | CH10: 4 | CI10: 0 | CJ10: 0 | CK10: 0 | CL10: 0 | CM10: 600 | CN10: 600 | CO10: 0 | CP10: 0 | CQ10: ='Top Ten Disease (OPD)'!FC11 -> 0 | CR10: 5497 | CS10: 4580
A11: 10108 | B11: Rural Municipality | C11: Province 1 | D11: Taplejung | E11: Sirijanga Rural Municipality | F11: 240 | G11: 251 | H11: 248 | I11: 265 | J11: 267 | K11: 218 | L11: 274 | M11: 144 | N11: 49 | O11: 236 | P11: =Q11*12 -> 264 | Q11: 22 | R11: 222 | S11: 1 | T11: 255 | U11: 2 | V11: 2 | W11: 109 | X11: 0 | Y11: 0 | Z11: 1210 | AA11: 1065 | AB11: 153 | AC11: 164 | AD11: 11 | AE11: 281 | AF11: 288 | AG11: 292 | AH11: =AB11+AC11+AD11+AE11 -> 609 | AI11: =AF11+AG11 -> 580 | AJ11: 735 | AK11: 222 | AL11: 10 | AM11: 994 | AN11: =AJ11+AK11+AL11+AM11 -> 1961 | AO11: =AK11+AL11 -> 232 | AP11: 195 | AQ11: 26 | AR11: 7 | AS11: 45 | AT11: 167 | AU11: 16 | AV11: 93 | AW11: 133 | AX11: 5 | AY11: 16 | AZ11: 22 | BA11: 4 | BB11: 17 | BC11: 0 | BD11: 0 | BE11: 0 | BF11: 0 | BG11: 0 | BH11: 0 | BI11: 0 | BJ11: 0 | BK11: 2 | BL11: 0 | BM11: 0 | BN11: 0 | BO11: 6 | BP11: 0 | BQ11: =BM11+BN11+BO11+BP11 -> 6 | BR11: 114 | BS11: 179 | BT11: 103 | BU11: 335 | BV11: 81.74 | BW11: 0 | BX11: 0 | BY11: 0 | BZ11: 152.41667 | CA11: 1138 | CB11: 29.083333 | CC11: 312 | CD11: 0 | CE11: 0 | CF11: 0 | CG11: 0 | CH11: 2 | CI11: 3 | CJ11: 0 | CK11: 0 | CL11: 0 | CM11: 0 | CN11: 0 | CO11: 0 | CP11: 0 | CQ11: ='Top Ten Disease (OPD)'!FC12 -> 0 | CR11: 7237 | CS11: 6449
A12: 10109 | B12: Rural Municipality | C12: Province 1 | D12: Taplejung | E12: Sidingba Rural Municipality | F12: 208 | G12: 234 | H12: 209 | I12: 204 | J12: 184 | K12: 191 | L12: 238 | M12: 106 | N12: 82 | O12: 213 | P12: =Q12*12 -> 158 | Q12: 13.166667 | R12: 147 | S12: 3 | T12: 273 | U12: 22 | V12: 0 | W12: 107 | X12: 7 | Y12: 0 | Z12: 1049 | AA12: 926 | AB12: 154 | AC12: 27 | AD12: 0 | AE12: 335 | AF12: 187 | AG12: 308 | AH12: =AB12+AC12+AD12+AE12 -> 516 | AI12: =AF12+AG12 -> 495 | AJ12: 590 | AK12: 149 | AL12: 3 | AM12: 349 | AN12: =AJ12+AK12+AL12+AM12 -> 1091 | AO12: =AK12+AL12 -> 152 | AP12: 122 | AQ12: 22 | AR12: 22 | AS12: 99 | AT12: 141 | AU12: 19 | AV12: 49 | AW12: 86 | AX12: 1 | AY12: 52 | AZ12: 28 | BA12: 2 | BB12: 21 | BC12: 0 | BD12: 0 | BE12: 0 | BF12: 0 | BG12: 0 | BH12: 0 | BI12: 0 | BJ12: 0 | BK12: 0 | BL12: 0 | BM12: 0 | BN12: 0 | BO12: 4 | BP12: 0 | BQ12: =BM12+BN12+BO12+BP12 -> 4 | BR12: 142 | BS12: 238 | BT12: 43 | BU12: 248 | BV12: 30.2 | BW12: 1 | BX12: 0 | BY12: 0 | BZ12: 104.08333 | CA12: 910 | CB12: 25.416667 | CC12: 298 | CD12: 0 | CE12: 0 | CF12: 0 | CG12: 1 | CH12: 1 | CI12: 0 | CJ12: 0 | CK12: 0 | CL12: 0 | CM12: 0 | CN12: 0 | CO12: 0 | CP12: 0 | CQ12: ='Top Ten Disease (OPD)'!FC13 -> 0 | CR12: 4283 | CS12: 3714
A13: 102 | B13: District | C13: Province 1 | D13: Sankhuwasabha | E13: SANKHUWASABHA | F13: 2986 | G13: 3078 | H13: 2982 | I13: 2944 | J13: 3082 | K13: 2655 | L13: 3341 | M13: 1429 | N13: 884 | O13: 2950 | P13: =Q13*12 -> 1920 | Q13: 160 | R13: 1759 | S13: 97 | T13: 3028 | U13: 30 | V13: 2 | W13: 1076 | X13: 17 | Y13: 3 | Z13: 12323 | AA13: 10552 | AB13: 1860 | AC13: 198 | AD13: 6 | AE13: 2984 | AF13: 2051 | AG13: 2885 | AH13: =AB13+AC13+AD13+AE13 -> 5048 | AI13: =AF13+AG13 -> 4936 | AJ13: 4404 | AK13: 2337 | AL13: 69 | AM13: 5388 | AN13: =AJ13+AK13+AL13+AM13 -> 12198 | AO13: =AK13+AL13 -> 2406 | AP13: 2634 | AQ13: 663 | AR13: 1317 | AS13: 693 | AT13: 1825 | AU13: 311 | AV13: 1116 | AW13: 1372 | AX13: 193 | AY13: 15 | AZ13: 1697 | BA13: 14 | BB13: 314 | BC13: 1 | BD13: 1 | BE13: 0 | BF13: 0 | BG13: 0 | BH13: 0 | BI13: 49 | BJ13: 14 | BK13: 410 | BL13: 175 | BM13: 3 | BN13: 0 | BO13: 11 | BP13: 3 | BQ13: =BM13+BN13+BO13+BP13 -> 17 | BR13: 555 | BS13: 2859 | BT13: 582 | BU13: 2635 | BV13: 718.68667 | BW13: 1 | BX13: 10 | BY13: 0 | BZ13: 316.66667 | CA13: 2734 | CB13: 100.25 | CC13: 1012 | CD13: 73 | CE13: 2 | CF13: 0 | CG13: 9 | CH13: 87 | CI13: 6 | CJ13: 11 | CK13: 0 | CL13: 0 | CM13: 12 | CN13: 12 | CO13: 0 | CP13: 0 | CQ13: ='Top Ten Disease (OPD)'!FC14 -> 2 | CR13: 78672 | CS13: 61159
... A104: 11106 | B104: Rural Municipality | C104: Province 1 | D104: Jhapa | E104: Kamal Rural Municipality | F104: 813 | G104: 883 | H104: 881 | I104: 881 | J104: 917 | K104: 683 | L104: 698 | M104: 315 | N104: 0 | O104: 945 | P104: =Q104*12 -> 130 | Q104: 10.833333 | R104: 130 | S104: 0 | T104: 563 | U104: 49 | V104: 3 | W104: 173 | X104: 71 | Y104: 18 | Z104: 5194 | AA104: 4581 | AB104: 117 | AC104: 23 | AD104: 0 | AE104: 1191 | AF104: 130 | AG104: 928 | AH104: =AB104+AC104+AD104+AE104 -> 1331 | AI104: =AF104+AG104 -> 1058 | AJ104: 267 | AK104: 110 | AL104: 2 | AM104: 1771 | AN104: =AJ104+AK104+AL104+AM104 -> 2150 | AO104: =AK104+AL104 -> 112 | AP104: 88 | AQ104: 21 | AR104: 5 | AS104: 86 | AT104: 408 | AU104: 6 | AV104: 149 | AW104: 155 | AX104: 0 | AY104: 0 | AZ104: 1 | BA104: 0 | BB104: 0 | BC104: 0 | BD104: 0 | BE104: 0 | BF104: 0 | BG104: 0 | BH104: 0 | BI104: 0 | BJ104: 0 | BK104: 0 | BL104: 0 | BM104: 0 | BN104: 0 | BO104: 0 | BP104: 0 | BQ104: =BM104+BN104+BO104+BP104 -> 0 | BR104: 468 | BS104: 101 | BT104: 39 | BU104: 301 | BV104: 48.266667 | BW104: 0 | BX104: 0 | BY104: 0 | BZ104: 24 | CA104: 279 | CB104: 6 | CC104: 69 | CD104: 0 | CE104: 0 | CF104: 0 | CG104: 0 | CH104: 58 | CI104: 19 | CJ104: 18 | CK104: 0 | CL104: 0 | CM104: 4 | CN104: 4 | CO104: 5 | CP104: 2 | CQ104: ='Top Ten Disease (OPD)'!FC105 -> 7 | CR104: 5653 | CS104: 5606
A105: 11107 | B105: Municipality | C105: Province 1 | D105: Jhapa | E105: Damak Municipality | F105: 1929 | G105: 1867 | H105: 1672 | I105: 1672 | J105: 1627 | K105: 1277 | L105: 1483 | M105: 910 | N105: 13 | O105: 1287 | P105: =Q105*12 -> 36 | Q105: 3 | R105: 17 | S105: 1539 | T105: 1204 | U105: 7 | V105: 2 | W105: 1698 | X105: 8 | Y105: 2 | Z105: 8323 | AA105: 8351 | AB105: 188 | AC105: 75 | AD105: 11 | AE105: 0 | AF105: 218 | AG105: 0 | AH105: =AB105+AC105+AD105+AE105 -> 274 | AI105: =AF105+AG105 -> 218 | AJ105: 364 | AK105: 310 | AL105: 13 | AM105: 0 | AN105: =AJ105+AK105+AL105+AM105 -> 687 | AO105: =AK105+AL105 -> 323 | AP105: 244 | AQ105: 41 | AR105: 104 | AS105: 993 | AT105: 2110 | AU105: 810 | AV105: 1783 | AW105: 454 | AX105: 0 | AY105: 0 | AZ105: 12497 | BA105: 0 | BB105: 0 | BC105: 0 | BD105: 0 | BE105: 0 | BF105: 0 | BG105: 0 | BH105: 1 | BI105: 31 | BJ105: 71 | BK105: 81 | BL105: 225 | BM105: 0 | BN105: 0 | BO105: 0 | BP105: 0 | BQ105: =BM105+BN105+BO105+BP105 -> 0 | BR105: 1001 | BS105: 246 | BT105: 269 | BU105: 372 | BV105: 108.89333 | BW105: 279 | BX105: 15 | BY105: 477 | BZ105: 47 | CA105: 7 | CB105: =#DIV/0! -> #DIV/0! | CC105: 0 | CD105: 989 | CE105: 12 | CF105: 0 | CG105: 5 | CH105: 131 | CI105: 49 | CJ105: 47 | CK105: 0 | CL105: 0 | CM105: 582 | CN105: 582 | CO105: 5 | CP105: 2 | CQ105: ='Top Ten Disease (OPD)'!FC106 -> 3 | CR105: 34626 | CS105: 29132
A106: 11108 | B106: Municipality | C106: Province 1 | D106: Jhapa | E106: Gauradaha Municipality | F106: 1324 | G106: 1182 | H106: 1177 | I106: 1185 | J106: 1287 | K106: 997 | L106: 1079 | M106: 782 | N106: 109 | O106: 1173 | P106: =Q106*12 -> 298 | Q106: 24.833333 | R106: 285 | S106: 0 | T106: 1391 | U106: 0 | V106: 0 | W106: 327 | X106: 0 | Y106: 0 | Z106: 5769 | AA106: 5269 | AB106: 472 | AC106: 98 | AD106: 1 | AE106: 2264 | AF106: 613 | AG106: 2280 | AH106: =AB106+AC106+AD106+AE106 -> 2835 | AI106: =AF106+AG106 -> 2893 | AJ106: 1237 | AK106: 398 | AL106: 3 | AM106: 4458 | AN106: =AJ106+AK106+AL106+AM106 -> 6096 | AO106: =AK106+AL106 -> 401 | AP106: 129 | AQ106: 267 | AR106: 2 | AS106: 156 | AT106: 607 | AU106: 61 | AV106: 331 | AW106: 409 | AX106: 0 | AY106: 0 | AZ106: 0 | BA106: 0 | BB106: 0 | BC106: 0 | BD106: 0 | BE106: 0 | BF106: 0 | BG106: 0 | BH106: 0 | BI106: 0 | BJ106: 0 | BK106: 95 | BL106: 0 | BM106: 0 | BN106: 0 | BO106: 1 | BP106: 0 | BQ106: =BM106+BN106+BO106+BP106 -> 1 | BR106: 384 | BS106: 120 | BT106: 1 | BU106: 591 | BV106: 208.40667 | BW106: 0 | BX106: 0 | BY106: 0 | BZ106: 51.333333 | CA106: 567 | CB106: 16.75 | CC106: 187 | CD106: 0 | CE106: 0 | CF106: 0 | CG106: 0 | CH106: 46 | CI106: 34 | CJ106: 29 | CK106: 1 | CL106: 0 | CM106: 65 | CN106: 65 | CO106: 1 | CP106: 1 | CQ106: ='Top Ten Disease (OPD)'!FC107 -> 1 | CR106: 15830 | CS106: 14192
A107: 11109 | B107: Rural Municipality | C107: Province 1 | D107: Jhapa | E107: Gauriganj Rural Municipality | F107: 666 | G107: 659 | H107: 619 | I107: 616 | J107: 579 | K107: 512 | L107: 564 | M107: 465 | N107: 2 | O107: 477 | P107: =Q107*12 -> 187 | Q107: 15.583333 | R107: 181 | S107: 0 | T107: 669 | U107: 4 | V107: 3 | W107: 373 | X107: 9 | Y107: 8 | Z107: 1247 | AA107: 1684 | AB107: 213 | AC107: 66 | AD107: 0 | AE107: 1573 | AF107: 205 | AG107: 1360 | AH107: =AB107+AC107+AD107+AE107 -> 1852 | AI107: =AF107+AG107 -> 1565 | AJ107: 421 | AK107: 184 | AL107: 5 | AM107: 1864 | AN107: =AJ107+AK107+AL107+AM107 -> 2474 | AO107: =AK107+AL107 -> 189 | AP107: 142 | AQ107: 82 | AR107: 32 | AS107: 82 | AT107: 409 | AU107: 17 | AV107: 134 | AW107: 190 | AX107: 0 | AY107: 0 | AZ107: 6 | BA107: 1 | BB107: 1 | BC107: 0 | BD107: 0 | BE107: 0 | BF107: 0 | BG107: 0 | BH107: 0 | BI107: 1 | BJ107: 0 | BK107: 95 | BL107: 0 | BM107: 0 | BN107: 0 | BO107: 0 | BP107: 0 | BQ107: =BM107+BN107+BO107+BP107 -> 0 | BR107: 125 | BS107: 235 | BT107: 62 | BU107: 316 | BV107: 111.30667 | BW107: 0 | BX107: 0 | BY107: 0 | BZ107: 40 | CA107: 420 | CB107: 15.5 | CC107: 167 | CD107: 0 | CE107: 0 | CF107: 0 | CG107: 0 | CH107: 19 | CI107: 10 | CJ107: 9 | CK107: 0 | CL107: 0 | CM107: 559 | CN107: 559 | CO107: 3 | CP107: 3 | CQ107: ='Top Ten Disease (OPD)'!FC108 -> 6 | CR107: 8869 | CS107: 7271
A108: 11110 | B108: Rural Municipality | C108: Province 1 | D108: Jhapa | E108: Jhapa Rural Municipality | F108: 778 | G108: 690 | H108: 505 | I108: 546 | J108: 597 | K108: 344 | L108: 394 | M108: 484 | N108: 119 | O108: 782 | P108: =Q108*12 -> 137 | Q108: 11.416667 | R108: 133 | S108: 0 | T108: 849 | U108: 10 | V108: 12 | W108: 563 | X108: 4 | Y108: 5 | Z108: 4467 | AA108: 3683 | AB108: 304 | AC108: 19 | AD108: 0 | AE108: 574 | AF108: 324 | AG108: 686 | AH108: =AB108+AC108+AD108+AE108 -> 897 | AI108: =AF108+AG108 -> 1010 | AJ108: 782 | AK108: 134 | AL108: 0 | AM108: 687 | AN108: =AJ108+AK108+AL108+AM108 -> 1603 | AO108: =AK108+AL108 -> 134 | AP108: 110 | AQ108: 9 | AR108: 21 | AS108: 144 | AT108: 517 | AU108: 24 | AV108: 217 | AW108: 262 | AX108: 0 | AY108: 0 | AZ108: 0 | BA108: 0 | BB108: 0 | BC108: 0 | BD108: 0 | BE108: 0 | BF108: 0 | BG108: 0 | BH108: 0 | BI108: 0 | BJ108: 0 | BK108: 0 | BL108: 0 | BM108: 0 | BN108: 0 | BO108: 0 | BP108: 0 | BQ108: =BM108+BN108+BO108+BP108 -> 0 | BR108: 135 | BS108: 157 | BT108: 10 | BU108: 232 | BV108: 93.966667 | BW108: 0 | BX108: 0 | BY108: 0 | BZ108: 28.5 | CA108: 267 | CB108: 7.5833333 | CC108: 87 | CD108: 0 | CE108: 0 | CF108: 0 | CG108: 0 | CH108: 21 | CI108: 14 | CJ108: 13 | CK108: 0 | CL108: 0 | CM108: 29 | CN108: 29 | CO108: 11 | CP108: 6 | CQ108: ='Top Ten Disease (OPD)'!FC109 -> 11 | CR108: 8306 | CS108: 7744
A109: 11111 | B109: Rural Municipality | C109: Province 1 | D109: Jhapa | E109: Barhadashi Rural Municipality | F109: 817 | G109: 760 | H109: 701 | I109: 686 | J109: 671 | K109: 420 | L109: 565 | M109: 464 | N109: 79 | O109: 572 | P109: =Q109*12 -> 177 | Q109: 14.75 | R109: 176 | S109: 4 | T109: 662 | U109: 21 | V109: 7 | W109: 223 | X109: 25 | Y109: 11 | Z109: 4075 | AA109: 3350 | AB109: 351 | AC109: 58 | AD109: 10 | AE109: 968 | AF109: 389 | AG109: 1467 | AH109: =AB109+AC109+AD109+AE109 -> 1387 | AI109: =AF109+AG109 -> 1856 | AJ109: 649 | AK109: 189 | AL109: 0 | AM109: 1762 | AN109: =AJ109+AK109+AL109+AM109 -> 2600 | AO109: =AK109+AL109 -> 189 | AP109: 107 | AQ109: 73 | AR109: 18 | AS109: 81 | AT109: 376 | AU109: 47 | AV109: 264 | AW109: 263 | AX109: 0 | AY109: 0 | AZ109: 93 | BA109: 0 | BB109: 59 | BC109: 0 | BD109: 0 | BE109: 0 | BF109: 0 | BG109: 0 | BH109: 0 | BI109: 0 | BJ109: 0 | BK109: 0 | BL109: 0 | BM109: 0 | BN109: 0 | BO109: 0 | BP109: 4 | BQ109: =BM109+BN109+BO109+BP109 -> 4 | BR109: 354 | BS109: 288 | BT109: 192 | BU109: 323 | BV109: 130.28 | BW109: 0 | BX109: 0 | BY109: 0 | BZ109: 31 | CA109: 350 | CB109: 12 | CC109: 126 | CD109: 0 | CE109: 0 | CF109: 23 | CG109: 0 | CH109: 27 | CI109: 20 | CJ109: 15 | CK109: 0 | CL109: 0 | CM109: 3 | CN109: 3 | CO109: 4 | CP109: 0 | CQ109: ='Top Ten Disease (OPD)'!FC110 -> 5 | CR109: 8795 | CS109: 7252
A110: 11112 | B110: Municipality | C110: Province 1 | D110: Jhapa | E110: Birtamod Municipality | F110: 2220 | G110: 2171 | H110: 2198 | I110: 2199 | J110: 2187 | K110: 1786 | L110: 2286 | M110: 1551 | N110: 29 | O110: 752 | P110: =Q110*12 -> 335 | Q110: 27.916667 | R110: 304 | S110: 294 | T110: 2348 | U110: 1 | V110: 0 | W110: 2719 | X110: 0 | Y110: 0 | Z110: 10342 | AA110: 9138 | AB110: 607 | AC110: 77 | AD110: 0 | AE110: 1343 | AF110: 464 | AG110: 1370 | AH110: =AB110+AC110+AD110+AE110 -> 2027 | AI110: =AF110+AG110 -> 1834 | AJ110: 1347 | AK110: 225 | AL110: 0 | AM110: 1900 | AN110: =AJ110+AK110+AL110+AM110 -> 3472 | AO110: =AK110+AL110 -> 225 | AP110: 187 | AQ110: 133 | AR110: 4 | AS110: 445 | AT110: 6675 | AU110: 15 | AV110: 624 | AW110: 398 | AX110: 2 | AY110: 0 | AZ110: 1005 | BA110: 0 | BB110: 339 | BC110: 0 | BD110: 0 | BE110: 0 | BF110: 0 | BG110: 0 | BH110: 0 | BI110: 61 | BJ110: 81 | BK110: 637 | BL110: 636 | BM110: 0 | BN110: 0 | BO110: 0 | BP110: 0 | BQ110: =BM110+BN110+BO110+BP110 -> 0 | BR110: 404 | BS110: 2636 | BT110: 987 | BU110: 605 | BV110: 193.86667 | BW110: 0 | BX110: 0 | BY110: 0 | BZ110: 35 | CA110: 395 | CB110: 13 | CC110: 138 | CD110: 0 | CE110: 0 | CF110: 8 | CG110: 9 | CH110: 102 | CI110: 45 | CJ110: 36 | CK110: 0 | CL110: 0 | CM110: 1753 | CN110: 1753 | CO110: 14 | CP110: 8 | CQ110: ='Top Ten Disease (OPD)'!FC111 -> 67 | CR110: 148645 | CS110: 118669
A111: 11113 | B111: Rural Municipality | C111: Province 1 | D111: Jhapa | E111: Haldibari Rural Municipality | F111: 718 | G111: 688 | H111: 644 | I111: 643 | J111: 621 | K111: 517 | L111: 592 | M111: 592 | N111: 20 | O111: 501 | P111: =Q111*12 -> 116 | Q111: 9.6666667 | R111: 114 | S111: 0 | T111: 383 | U111: 2 | V111: 0 | W111: 574 | X111: 4 | Y111: 0 | Z111: 2898 | AA111: 2784 | AB111: 473 | AC111: 85 | AD111: 0 | AE111: 1513 | AF111: 429 | AG111: 1360 | AH111: =AB111+AC111+AD111+AE111 -> 2071 | AI111: =AF111+AG111 -> 1789 | AJ111: 911 | AK111: 200 | AL111: 1 | AM111: 1956 | AN111: =AJ111+AK111+AL111+AM111 -> 3068 | AO111: =AK111+AL111 -> 201 | AP111: 94 | AQ111: 110 | AR111: 7 | AS111: 110 | AT111: 405 | AU111: 116 | AV111: 280 | AW111: 373 | AX111: 0 | AY111: 0 | AZ111: 0 | BA111: 0 | BB111: 0 | BC111: 0 | BD111: 0 | BE111: 0 | BF111: 0 | BG111: 0 | BH111: 0 | BI111: 0 | BJ111: 0 | BK111: 0 | BL111: 0 | BM111: 0 | BN111: 0 | BO111: 0 | BP111: 0 | BQ111: =BM111+BN111+BO111+BP111 -> 0 | BR111: 288 | BS111: 218 | BT111: 3 | BU111: 377 | BV111: 128.53333 | BW111: 0 | BX111: 0 | BY111: 0 | BZ111: 31.166667 | CA111: 371 | CB111: 10 | CC111: 106 | CD111: 0 | CE111: 0 | CF111: 3 | CG111: 0 | CH111: 28 | CI111: 16 | CJ111: 15 | CK111: 0 | CL111: 0 | CM111: 6 | CN111: 6 | CO111: 1 | CP111: 0 | CQ111: ='Top Ten Disease (OPD)'!FC112 -> 2 | CR111: 10670 | CS111: 8172
A112: 11114 | B112: Municipality | C112: Province 1 | D112: Jhapa | E112: Bhadrapur Municipality | F112: 1860 | G112: 1565 | H112: 1569 | I112: 1569 | J112: 1460 | K112: 1193 | L112: 1378 | M112: 1379 | N112: 0 | O112: 891 | P112: =Q112*12 -> 282 | Q112: 23.5 | R112: 274 | S112: 100 | T112: 948 | U112: 12 | V112: 11 | W112: 656 | X112: 71 | Y112: 34 | Z112: 6444 | AA112: 5823 | AB112: 355 | AC112: 47 | AD112: 10 | AE112: 1079 | AF112: 418 | AG112: 1225 | AH112: =AB112+AC112+AD112+AE112 -> 1491 | AI112: =AF112+AG112 -> 1643 | AJ112: 1053 | AK112: 289 | AL112: 24 | AM112: 1286 | AN112: =AJ112+AK112+AL112+AM112 -> 2652 | AO112: =AK112+AL112 -> 313 | AP112: 225 | AQ112: 43 | AR112: 99 | AS112: 264 | AT112: 2332 | AU112: 210 | AV112: 1098 | AW112: 1230 | AX112: 0 | AY112: 1 | AZ112: 1923 | BA112: 0 | BB112: 41 | BC112: 0 | BD112: 0 | BE112: 0 | BF112: 0 | BG112: 0 | BH112: 1 | BI112: 0 | BJ112: 0 | BK112: 82 | BL112: 0 | BM112: 0 | BN112: 0 | BO112: 1 | BP112: 0 | BQ112: =BM112+BN112+BO112+BP112 -> 1 | BR112: 1066 | BS112: 1142 | BT112: 680 | BU112: 960 | BV112: 382.94 | BW112: 0 | BX112: 0 | BY112: 51 | BZ112: 59.416667 | CA112: 378 | CB112: 14.083333 | CC112: 145 | CD112: 5600 | CE112: 52 | CF112: 1 | CG112: 0 | CH112: 54 | CI112: 25 | CJ112: 25 | CK112: 1 | CL112: 0 | CM112: 522 | CN112: 522 | CO112: 8 | CP112: 13 | CQ112: ='Top Ten Disease (OPD)'!FC113 -> 56 | CR112: 20728 | CS112: 18750
A113: 11115 | B113: Rural Municipality | C113: Province 1 | D113: Jhapa | E113: Kachanakawal Rural Municipality | F113: 832 | G113: 845 | H113: 802 | I113: 802 | J113: 772 | K113: 537 | L113: 715 | M113: 687 | N113: 113 | O113: 387 | P113: =Q113*12 -> 262 | Q113: 21.833333 | R113: 257 | S113: 1 | T113: 675 | U113: 7 | V113: 0 | W113: 102 | X113: 11 | Y113: 0 | Z113: 4507 | AA113: 4669 | AB113: 361 | AC113: 85 | AD113: 0 | AE113: 1443 | AF113: 378 | AG113: 1363 | AH113: =AB113+AC113+AD113+AE113 -> 1889 | AI113: =AF113+AG113 -> 1741 | AJ113: 665 | AK113: 409 | AL113: 26 | AM113: 1118 | AN113: =AJ113+AK113+AL113+AM113 -> 2218 | AO113: =AK113+AL113 -> 435 | AP113: 190 | AQ113: 150 | AR113: 97 | AS113: 84 | AT113: 564 | AU113: 36 | AV113: 385 | AW113: 433 | AX113: 2 | AY113: 6 | AZ113: 72 | BA113: 0 | BB113: 37 | BC113: 0 | BD113: 0 | BE113: 0 | BF113: 0 | BG113: 0 | BH113: 0 | BI113: 2 | BJ113: 0 | BK113: 52 | BL113: 0 | BM113: 0 | BN113: 0 | BO113: 3 | BP113: 0 | BQ113: =BM113+BN113+BO113+BP113 -> 3 | BR113: 243 | BS113: 489 | BT113: 168 | BU113: 515 | BV113: 122.2 | BW113: 0 | BX113: 0 | BY113: 0 | BZ113: 59.083333 | CA113: 464 | CB113: 24 | CC113: 265 | CD113: 0 | CE113: 0 | CF113: 18 | CG113: 0 | CH113: 44 | CI113: 17 | CJ113: 25 | CK113: 1 | CL113: 0 | CM113: 704 | CN113: 704 | CO113: 11 | CP113: 10 | CQ113: ='Top Ten Disease (OPD)'!FC114 -> 25 | CR113: 21628 | CS113: 19240
A114: 112 | B114: District | C114: Province 1 | D114: Morang | E114: MORANG | F114: 24234 | G114: 21570 | H114: 20750 | I114: 20735 | J114: 20474 | K114: 16016 | L114: 17821 | M114: 9856 | N114: 8840 | O114: 15793 | P114: =Q114*12 -> 4058 | Q114: 338.16667 | R114: 3904 | S114: 3973 | T114: 15878 | U114: 178 | V114: 94 | W114: 8582 | X114: 261 | Y114: 141 | Z114: 77565 | AA114: 69122 | AB114: 5764 | AC114: 740 | AD114: 0 | AE114: 21212 | AF114: 7172 | AG114: 19660 | AH114: =AB114+AC114+AD114+AE114 -> 27716 | AI114: =AF114+AG114 -> 26832 | AJ114: 14239 | AK114: 3821 | AL114: 20 | AM114: 34755 | AN114: =AJ114+AK114+AL114+AM114 -> 52835 | AO114: =AK114+AL114 -> 3841 | AP114: 3981 | AQ114: 3600 | AR114: 3187 | AS114: 8848 | AT114: 31607 | AU114: 3072 | AV114: 9994 | AW114: 8355 | AX114: 8 | AY114: 1 | AZ114: 20175 | BA114: 13 | BB114: 5308 | BC114: 0 | BD114: 1 | BE114: 0 | BF114: 0 | BG114: 3 | BH114: 12 | BI114: 182 | BJ114: 57 | BK114: 1768 | BL114: 882 | BM114: 0 | BN114: 0 | BO114: 11 | BP114: 140 | BQ114: =BM114+BN114+BO114+BP114 -> 151 | BR114: 5517 | BS114: 9315 | BT114: 3310 | BU114: 14451 | BV114: 2365.88 | BW114: 560 | BX114: 3 | BY114: 3 | BZ114: 766.5 | CA114: 8492 | CB114: 254.83333 | CC114: 2935 | CD114: 5081 | CE114: 45 | CF114: 9 | CG114: 100 | CH114: 1016 | CI114: 556 | CJ114: 483 | CK114: 9 | CL114: 3 | CM114: 4940 | CN114: 4928 | CO114: 64 | CP114: 57 | CQ114: ='Top Ten Disease (OPD)'!FC115 -> 87 | CR114: 581746 | CS114: 451127
A115: 11201 | B115: Rural Municipality | C115: Province 1 | D115: Morang | E115: Miklajung Rural Municipality | F115: 647 | G115: 653 | H115: 691 | I115: 691 | J115: 642 | K115: 532 | L115: 624 | M115: 391 | N115: 93 | O115: 610 | P115: =Q115*12 -> 149 | Q115: 12.416667 | R115: 149 | S115: 3 | T115: 646 | U115: 0 | V115: 0 | W115: 415 | X115: 3 | Y115: 0 | Z115: 1770 | AA115: 1614 | AB115: 305 | AC115: 3 | AD115: 0 | AE115: 524 | AF115: 349 | AG115: 487 | AH115: =AB115+AC115+AD115+AE115 -> 832 | AI115: =AF115+AG115 -> 836 | AJ115: 721 | AK115: 360 | AL115: 0 | AM115: 1482 | AN115: =AJ115+AK115+AL115+AM115 -> 2563 | AO115: =AK115+AL115 -> 360 | AP115: 209 | AQ115: 179 | AR115: 21 | AS115: 119 | AT115: 399 | AU115: 65 | AV115: 214 | AW115: 281 | AX115: 0 | AY115: 0 | AZ115: 26 | BA115: 0 | BB115: 26 | BC115: 0 | BD115: 0 | BE115: 0 | BF115: 0 | BG115: 0 | BH115: 0 | BI115: 3 | BJ115: 0 | BK115: 75 | BL115: 0 | BM115: 0 | BN115: 0 | BO115: 2 | BP115: 0 | BQ115: =BM115+BN115+BO115+BP115 -> 2 | BR115: 77 | BS115: 92 | BT115: 0 | BU115: 203 | BV115: 87.846667 | BW115: 0 | BX115: 0 | BY115: 0 | BZ115: 27.25 | CA115: 302 | CB115: 12.166667 | CC115: 144 | CD115: 0 | CE115: 0 | CF115: 0 | CG115: 0 | CH115: 20 | CI115: 24 | CJ115: 10 | CK115: 0 | CL115: 0 | CM115: 448 | CN115: 448 | CO115: 0 | CP115: 0 | CQ115: ='Top Ten Disease (OPD)'!FC116 -> 0 | CR115: 10077 | CS115: 7489
A116: 11202 | B116: Municipality | C116: Province 1 | D116: Morang | E116: Letang Municipality | F116: 715 | G116: 692 | H116: 687 | I116: 687 | J116: 677 | K116: 702 | L116: 746 | M116: 368 | N116: 251 | O116: 808 | P116: =Q116*12 -> 199 | Q116: 16.583333 | R116: 199 | S116: 2 | T116: 749 | U116: 2 | V116: 5 | W116: 581 | X116: 0 | Y116: 0 | Z116: 3687 | AA116: 3314 | AB116: 151 | AC116: 10 | AD116: 0 | AE116: 637 | AF116: 155 | AG116: 525 | AH116: =AB116+AC116+AD116+AE116 -> 798 | AI116: =AF116+AG116 -> 680 | AJ116: 585 | AK116: 244 | AL116: 0 | AM116: 1038 | AN116: =AJ116+AK116+AL116+AM116 -> 1867 | AO116: =AK116+AL116 -> 244 | AP116: 130 | AQ116: 102 | AR116: 178 | AS116: 101 | AT116: 451 | AU116: 66 | AV116: 299 | AW116: 365 | AX116: 0 | AY116: 0 | AZ116: 123 | BA116: 2 | BB116: 34 | BC116: 0 | BD116: 1 | BE116: 0 | BF116: 0 | BG116: 0 | BH116: 0 | BI116: 23 | BJ116: 10 | BK116: 126 | BL116: 10 | BM116: 0 | BN116: 0 | BO116: 0 | BP116: 0 | BQ116: =BM116+BN116+BO116+BP116 -> 0 | BR116: 121 | BS116: 205 | BT116: 220 | BU116: 401 | BV116: 109.43333 | BW116: 0 | BX116: 0 | BY116: 0 | BZ116: 33.666667 | CA116: 389 | CB116: 11.833333 | CC116: 138 | CD116: 2 | CE116: 0 | CF116: 2 | CG116: 1 | CH116: 39 | CI116: 33 | CJ116: 25 | CK116: 0 | CL116: 0 | CM116: 254 | CN116: 254 | CO116: 2 | CP116: 1 | CQ116: ='Top Ten Disease (OPD)'!FC117 -> 3 | CR116: 7226 | CS116: 5368
A117: 11203 | B117: Rural Municipality | C117: Province 1 | D117: Morang | E117: Kerabari Rural Municipality | F117: 535 | G117: 604 | H117: 629 | I117: 632 | J117: 583 | K117: 445 | L117: 472 | M117: 164 | N117: 275 | O117: 534 | P117: =Q117*12 -> 201 | Q117: 16.75 | R117: 201 | S117: 4 | T117: 627 | U117: 3 | V117: 0 | W117: 178 | X117: 1 | Y117: 0 | Z117: 2760 | AA117: 2388 | AB117: 536 | AC117: 31 | AD117: 0 | AE117: 1041 | AF117: 556 | AG117: 1012 | AH117: =AB117+AC117+AD117+AE117 -> 1608 | AI117: =AF117+AG117 -> 1568 | AJ117: 704 | AK117: 171 | AL117: 5 | AM117: 1672 | AN117: =AJ117+AK117+AL117+AM117 -> 2552 | AO117: =AK117+AL117 -> 176 | AP117: 135 | AQ117: 112 | AR117: 97 | AS117: 158 | AT117: 390 | AU117: 48 | AV117: 183 | AW117: 288 | AX117: 0 | AY117: 1 | AZ117: 149 | BA117: 9 | BB117: 154 | BC117: 0 | BD117: 0 | BE117: 0 | BF117: 0 | BG117: 0 | BH117: 0 | BI117: 2 | BJ117: 0 | BK117: 77 | BL117: 0 | BM117: 0 | BN117: 0 | BO117: 0 | BP117: 1 | BQ117: =BM117+BN117+BO117+BP117 -> 1 | BR117: 250 | BS117: 149 | BT117: 7 | BU117: 328 | BV117: 96.573333 | BW117: 0 | BX117: 0 | BY117: 0 | BZ117: 39.75 | CA117: 406 | CB117: 10.833333 | CC117: 125 | CD117: 0 | CE117: 0 | CF117: 0 | CG117: 0 | CH117: 56 | CI117: 12 | CJ117: 12 | CK117: 4 | CL117: 1 | CM117: 220 | CN117: 220 | CO117: 3 | CP117: 0 | CQ117: ='Top Ten Disease (OPD)'!FC118 -> 3 | CR117: 10721 | CS117: 9360
... A838: 70909 | B838: Rural Municipality | C838: Sudurpashchim Province | D838: Kanchanpur | E838: Beldandi Rural Municipality | F838: 407 | G838: 400 | H838: 354 | I838: 354 | J838: 344 | K838: 305 | L838: 342 | M838: 188 | N838: 259 | O838: 380 | P838: =Q838*12 -> 108 | Q838: 9 | R838: 108 | S838: 20 | T838: 240 | U838: 23 | V838: 13 | W838: 221 | X838: 21 | Y838: 9 | Z838: 2579 | AA838: 2276 | AB838: 245 | AC838: 46 | AD838: 1 | AE838: 1793 | AF838: 218 | AG838: 1678 | AH838: =AB838+AC838+AD838+AE838 -> 2085 | AI838: =AF838+AG838 -> 1896 | AJ838: 349 | AK838: 138 | AL838: 0 | AM838: 1682 | AN838: =AJ838+AK838+AL838+AM838 -> 2169 | AO838: =AK838+AL838 -> 138 | AP838: 92 | AQ838: 35 | AR838: 15 | AS838: 75 | AT838: 406 | AU838: 43 | AV838: 306 | AW838: 365 | AX838: 0 | AY838: 0 | AZ838: 303 | BA838: 0 | BB838: 153 | BC838: 1 | BD838: 0 | BE838: 0 | BF838: 0 | BG838: 0 | BH838: 0 | BI838: 3 | BJ838: 0 | BK838: 110 | BL838: 5 | BM838: 0 | BN838: 0 | BO838: 1 | BP838: 0 | BQ838: =BM838+BN838+BO838+BP838 -> 1 | BR838: 236 | BS838: 409 | BT838: 0 | BU838: 790 | BV838: 329.46667 | BW838: 0 | BX838: 0 | BY838: 0 | BZ838: 47.833333 | CA838: 503 | CB838: 8 | CC838: 87 | CD838: 0 | CE838: 0 | CF838: 0 | CG838: 1 | CH838: 29 | CI838: 13 | CJ838: 11 | CK838: 1 | CL838: 0 | CM838: 1985 | CN838: 1985 | CO838: 1 | CP838: 0 | CQ838: ='Top Ten Disease (OPD)'!FC839 -> 1 | CR838: 10536 | CS838: 6253
B839: Nepal | C839: Nepal | E839: Nepal | F839: 573796 | G839: 550619 | H839: 509979 | I839: 513111 | J839: 497126 | K839: 409771 | L839: 492017 | M839: 269807 | N839: 202262 | O839: 436251 | P839: =Q839*12 -> 177079 | Q839: 14756.583 | R839: 167949 | S839: 32509 | T839: 504219.5 | U839: 14310 | V839: 4586 | W839: 325431 | X839: 14905 | Y839: 4807 | Z839: 2225848 | AA839: 1955128 | AB839: 312006 | AC839: 62808 | AD839: 1746 | AE839: 771706 | AF839: 378837 | AG839: 714479 | AH839: =AB839+AC839+AD839+AE839 -> 1148266 | AI839: =AF839+AG839 -> 1093316 | AJ839: 565613 | AK839: 155394 | AL839: 4419 | AM839: 1025242 | AN839: =AJ839+AK839+AL839+AM839 -> 1750668 | AO839: =AK839+AL839 -> 159813 | AP839: 162973 | AQ839: 77312 | AR839: 68266 | AS839: 119391 | AT839: 541994 | AU839: 52188 | AV839: 268455 | AW839: 289625 | AX839: 21034 | AY839: 7086 | AZ839: 327635 | BA839: 3671 | BB839: 99585 | BC839: 37 | BD839: 41 | BE839: 66 | BF839: 9 | BG839: 29 | BH839: 57 | BI839: 5862 | BJ839: 4265 | BK839: 55298 | BL839: 33215 | BM839: 86 | BN839: 5 | BO839: 1383 | BP839: 716 | BQ839: =BM839+BN839+BO839+BP839 -> 2190 | BR839: 163192 | BS839: 300249 | BT839: 143282 | BU839: 359487 | BV839: 194885.04 | BW839: 3545 | BX839: 441 | BY839: 2027 | BZ839: 49249.667 | CA839: 517285 | CB839: 12146 | CC839: 131382 | CD839: 139567 | CE839: 2013 | CF839: 933 | CG839: 5029 | CH839: 25875 | CI839: 12182 | CJ839: 10505 | CK839: 1187 | CL839: 77 | CM839: 207828 | CN839: 207581 | CO839: 1722 | CP839: 1465 | CQ839: ='Top Ten Disease (OPD)'!FC840 -> 6327 | CR839: 12025279 | CS839: 9324237
AI840: =AI839/AH839*100 -> 95.214523

Sheet Health Facilities
F1: Public Health Facilities | M1: Non-public health facilities | N1: Total health facilities (Public and Non-Public)
A2: Code | B2: Governance Units | C2: Provinces | D2: Districts | E2: Name of Government Unit | F2: Hospital | G2: Primary Health Care Centers | H2: Health Post | I2: Urban Health Centers | J2: Community Health Unit | K2: Other Health Facilities | L2: Total
A3: 1 | B3: Province | C3: Province 1 | D3: Province | E3: Province 1 | F3: 18 | G3: 40 | H3: 648 | I3: 52 | J3: 49 | K3: 9 | L3: 816 | M3: 136 | N3: 952
A4: 101 | B4: District | C4: Province 1 | D4: Taplejung | E4: TAPLEJUNG | F4: 1 | G4: 2 | H4: 50 | I4: 2 | J4: 11 | K4: 0 | L4: 66 | M4: 5 | N4: 71
A5: 10101 | B5: Rural Municipality | C5: Province 1 | D5: Taplejung | E5: Phaktanlung Rural Municipality | F5: 0 | G5: 0 | H5: 7 | I5: 0 | J5: 2 | K5: 0 | L5: 9 | M5: 0 | N5: 9
A6: 10102 | B6: Rural Municipality | C6: Province 1 | D6: Taplejung | E6: Mikwakhola Rural Municipality | F6: 0 | G6: 0 | H6: 4 | I6: 0 | J6: 1 | K6: 0 | L6: 5 | M6: 0 | N6: 5
A7: 10103 | B7: Rural Municipality | C7: Province 1 | D7: Taplejung | E7: Meringden Rural Municipality | F7: 0 | G7: 0 | H7: 6 | I7: 0 | J7: 1 | K7: 0 | L7: 7 | M7: 0 | N7: 7
A8: 10104 | B8: Rural Municipality | C8: Province 1 | D8: Taplejung | E8: Maiwakhola Rural Municipality | F8: 0 | G8: 1 | H8: 2 | I8: 0 | J8: 3 | K8: 0 | L8: 6 | M8: 0 | N8: 6
A9: 10105 | B9: Rural Municipality | C9: Province 1 | D9: Taplejung | E9: Aatharai Tribeni Rural Municipality | F9: 0 | G9: 0 | H9: 7 | I9: 0 | J9: 0 | K9: 0 | L9: 7 | M9: 0 | N9: 7
A10: 10106 | B10: Municipality | C10: Province 1 | D10: Taplejung | E10: Phungling Municipality | F10: 1 | G10: 0 | H10: 4 | I10: 2 | J10: 3 | K10: 0 | L10: 10 | M10: 5 | N10: 15
A11: 10107 | B11: Rural Municipality | C11: Province 1 | D11: Taplejung | E11: Yangwarak Rural Municipality | F11: 0 | G11: 0 | H11: 6 | I11: 0 | J11: 0 | K11: 0 | L11: 6 | M11: 0 | N11: 6
A12: 10108 | B12: Rural Municipality | C12: Province 1 | D12: Taplejung | E12: Sirijanga Rural Municipality | F12: 0 | G12: 1 | H12: 7 | I12: 0 | J12: 1 | K12: 0 | L12: 9 | M12: 0 | N12: 9
A13: 10109 | B13: Rural Municipality | C13: Province 1 | D13: Taplejung | E13: Sidingba Rural Municipality | F13: 0 | G13: 0 | H13: 7 | I13: 0 | J13: 0 | K13: 0 | L13: 7 | M13: 0 | N13: 7
A14: 102 | B14: District | C14: Province 1 | D14: Sankhuwasabha | E14: SANKHUWASABHA | F14: 1 | G14: 2 | H14: 36 | I14: 8 | J14: 8 | K14: 0 | L14: 55 | M14: 8 | N14: 63
... A839: 70909 | B839: Rural Municipality | C839: Sudurpashchim Province | D839: Kanchanpur | E839: Beldandi Rural Municipality | F839: 0 | G839: 1 | H839: 1 | I839: 0 | J839: 0 | K839: 0 | L839: 2 | M839: 0 | N839: 2
B840: Nepal | C840: Nepal | E840: Nepal | F840: 125 | G840: 198 | H840: 3808 | I840: 374 | J840: 299 | K840: 59 | L840: 4863 | M840: 2071 | N840: 6934

Sheet Indicators
F1: Immunization | Q1: Nutrition | V1: IMNCI | AB1: Safe Motherhood | AJ1: Family Planning | AL1: FCHV | AP1: HIV/AIDS | AR1: Tuberclosis
A2: Code | B2: Governance Units | C2: Provinces | D2: Districts | E2: Name of Government Unit | F2: Percentage of children under one year immunized with BCG | G2: Percentage of children under one year immunized with DPT-HepB-Hib1 | H2: Percentage of children under one year immunized with DPT-HepB-Hib3 | I2: Percentage of children under one year immunized with polio 3 | J2: Percentage of children under one year immunized with PCV 3 | K2: Percentage of children aged 12-23 months immunized with measles/rubella 2 | L2: Percentage of children 12-23 months immunized with JE | M2: Percentage of children fully immunized as per NIP schedule | N2: Drop out DPT-HepB-Hib 1 vs 3 | O2: Percentage of pregnant women who received TD2 & TD2+ | P2: Percentage of planned immunization sessions conducted | Q2: Percentage of newborns with low birth weight (<2.5kg) among total delivery by HWs | R2: Percentage of children aged 0-23 months registered for (New) growth monitoring | S2: % of children aged 0-23 months registered for Growth Monitoring (New) who were Underweight | T2: % of children aged 6-59 months, who received Vitamin A supplements | U2: % of children aged 12-59 months who received antihelminthics/Deworming | V2: Diarrhoea incidence rate among children under five years | W2: Percentage of children under five years with diarrhea treated with zinc and ORS | X2: Incidence of ARI among children under five years (per 1000) | Y2: Incidence of pneumonia among children under five years (per 1000) (HF & Outreacah) | Z2: % of children under five years with ARI suffering pneumonia | AA2: Percentage of pneumonia cases treated with antibiotics (HF & ORC) | AB2: Percentage of pregnant women who had at least one ANC checkup | AC2: Percentage of pregnant women who had four ANC checkups as per protocol (4th, 6th, 8th and 9th month) | AD2: Percentage of women who received a 180 day supply of Iron Folic Acid during pregnancy | AE2: Percentage of institutional deliveries | AF2: Percentage of women who had 3 PNC check-ups as per protocol | AG2: Number of Maternal Deaths (SM+FCHV) | AH2: Number of Neonatal Deaths (IMNCI+SM+FCHV) | AI2: Total number of Abortion Cases | AJ2: Contraceptive prevalence rate (CPR)(modern spacing methods) among women of reproductive age (MWRA) | AK2: % of postpartum mothers using a modern family planning method (implant, IUCD) | AL2: Number of Female Community Health Volunteers (FCHVs) | AM2: Percentage of Mother groups meeting held | AN2: % of planned primary health care (PHC) outreach clinics conducted | AO2: Average number of clients served per PHC outreach clinic | AP2: Number of HIV tested | AQ2: Total new HIV positive cases | AR2: No. of new TB cases registered | AS2: TB Treatment Success Rate(Percentage) | AT2: Number of kala-azar cases in at risk districts | AU2: Number of lymphatic filariasis cases | AV2: Number of Dengue cases | AW2: Number of Trachoma cases | AX2: Number of new case detection of leprosy [Pausi Besilli (PB) and Multi Besilli (MB)] | AY2: Prevalence of leprosy per 10,000 population | AZ2: Number of outpatients (New) | BA2: % of population utilizing outpatient service | BB2: Outpatient sex ratio | BC2: Reporting Status-Dataset Reporting rate (%)
A3: 1 | B3: Province | C3: Province 1 | D3: Province | E3: Province 1 | F3: 90 | G3: 86.3 | H3: 82.3 | I3: 82.4 | J3: 82.5 | K3: 68.5 | L3: 79.4 | M3: 79.7 | N3: 4.6 | O3: 68.4 | P3: ='Raw Data'!R2/'Raw Data'!P2*100 -> 94.624593 | Q3: 14.9 | R3: 66.2 | S3: 2.5 | T3: ='Raw Data'!Z2/'Target Population'!M3*100 -> 88.386909 | U3: ='Raw Data'!AA2/'Target Population'!N3*100 -> 89.883647 | V3: ='Raw Data'!AH2/'Target Population'!L3*100 -> 36.366864 | W3: ='Raw Data'!AI2/'Raw Data'!AH2*100 -> 89.755908 | X3: ='Raw Data'!AN2/'Target Population'!L3*1000 -> 664.0453 | Y3: ='Raw Data'!AO2/'Target Population'!L3*1000 -> 68.468803 | Z3: ='Raw Data'!AO2/('Raw Data'!AJ2+'Raw Data'!AK2+'Raw Data'!AL2)*100 -> 23.43477 | AA3: =('Raw Data'!AP2+'Raw Data'!AQ2+'Raw Data'!AR2)/'Raw Data'!AO2*100 -> 172.72084 | AB3: 104.8 | AC3: 46.7 | AD3: 37.3 | AE3: 52.5 | AF3: 11.8 | AG3: ='Raw Data'!BC2+'Raw Data'!BD2+'Raw Data'!BE2+'Raw Data'!BF2+'Raw Data'!BG2+'Raw Data'!BH2 -> 41 | AH3: ='Raw Data'!BQ2 -> 511 | AI3: ='Raw Data'!BI2+'Raw Data'!BJ2+'Raw Data'!BK2+'Raw Data'!BL2 -> 15854 | AJ3: =('Raw Data'!BR2+'Raw Data'!BS2+'Raw Data'!BT2+'Raw Data'!BU2+'Raw Data'!BV2)/'Target Population'!Q3*100 -> 20.252254 | AK3: =SUM('Raw Data'!BW2:BY2)/'Target Population'!G3*100 -> 1.5137648 | AL3: ='Raw Data'!BZ2 -> 8662.6667 | AM3: ='Raw Data'!CA2/('Raw Data'!BZ2*12)*100 -> 84.34566 | AN3: ='Raw Data'!CC2/('Raw Data'!CB2*12)*100 -> 92.928534 | AO3: 17.8 | AP3: ='Raw Data'!CD2 -> 14714 | AQ3: ='Raw Data'!CE2 -> 142 | AR3: 3587 | AS3: 88.6 | AT3: 54 | AU3: ='Top Ten Disease (OPD)'!HF3 -> 103 | AV3: ='Top Ten Disease (OPD)'!HD3 -> 131 | AW3: ='Raw Data'!CG2 -> 734 | AX3: ='Raw Data'!CO2+'Raw Data'!CP2 -> 367 | AY3: 7.7 | AZ3: ='Raw Data'!CR2+'Raw Data'!CS2 -> 3670567 | BA3: =AZ3/'Target Population'!F3*100 -> 75.93446 | BB3: ='Raw Data'!CS2/'Raw Data'!CR2*100 -> 79.017119 | BC3: 94.9
A4: 101 | B4: District | C4: Province 1 | D4: Taplejung | E4: TAPLEJUNG | F4: 91.6 | G4: 89.8 | H4: 84.1 | I4: 85 | J4: 80.3 | K4: 70.7 | L4: 93.3 | M4: 66.7 | N4: 6.3 | O4: 68.4 | P4: ='Raw Data'!R3/'Raw Data'!P3*100 -> 88.93643 | Q4: 2.9 | R4: 69.5 | S4: 3.3 | T4: ='Raw Data'!Z3/'Target Population'!M4*100 -> 84.393355 | U4: ='Raw Data'!AA3/'Target Population'!N4*100 -> 85.436523 | V4: ='Raw Data'!AH3/'Target Population'!L4*100 -> 53.368808 | W4: ='Raw Data'!AI3/'Raw Data'!AH3*100 -> 94.158124 | X4: ='Raw Data'!AN3/'Target Population'!L4*1000 -> 892.37803 | Y4: ='Raw Data'!AO3/'Target Population'!L4*1000 -> 104.47426 | Z4: ='Raw Data'!AO3/('Raw Data'!AJ3+'Raw Data'!AK3+'Raw Data'!AL3)*100 -> 20.53624 | AA4: =('Raw Data'!AP3+'Raw Data'!AQ3+'Raw Data'!AR3)/'Raw Data'!AO3*100 -> 100.21521 | AB4: 81 | AC4: 31.2 | AD4: 35 | AE4: 39 | AF4: 16 | AG4: ='Raw Data'!BC3+'Raw Data'!BD3+'Raw Data'!BE3+'Raw Data'!BF3+'Raw Data'!BG3+'Raw Data'!BH3 -> 5 | AH4: ='Raw Data'!BQ3 -> 45 | AI4: ='Raw Data'!BI3+'Raw Data'!BJ3+'Raw Data'!BK3+'Raw Data'!BL3 -> 496 | AJ4: =('Raw Data'!BR3+'Raw Data'!BS3+'Raw Data'!BT3+'Raw Data'!BU3+'Raw Data'!BV3)/'Target Population'!Q4*100 -> 22.543454 | AK4: =SUM('Raw Data'!BW3:BY3)/'Target Population'!G4*100 -> 0.10183299 | AL4: ='Raw Data'!BZ3 -> 872.41667 | AM4: ='Raw Data'!CA3/('Raw Data'!BZ3*12)*100 -> 54.685261 | AN4: ='Raw Data'!CC3/('Raw Data'!CB3*12)*100 -> 91.383326 | AO4: 10.6 | AP4: ='Raw Data'!CD3 -> 0 | AQ4: ='Raw Data'!CE3 -> 0 | AR4: 54 | AS4: 66.7 | AT4: 0 | AU4: ='Top Ten Disease (OPD)'!HF4 -> 0 | AV4: ='Top Ten Disease (OPD)'!HD4 -> 0 | AW4: ='Raw Data'!CG3 -> 73 | AX4: ='Raw Data'!CO3+'Raw Data'!CP3 -> 0 | AY4: 0 | AZ4: ='Raw Data'!CR3+'Raw Data'!CS3 -> 111948 | BA4: =AZ4/'Target Population'!F4*100 -> 86.027157 | BB4: ='Raw Data'!CS3/'Raw Data'!CR3*100 -> 88.100479 | BC4: 94.3
A5: 10101 | B5: Rural Municipality | C5: Province 1 | D5: Taplejung | E5: Phaktanlung Rural Municipality | F5: 105.2 | G5: 110.8 | H5: 105.6 | I5: 104.5 | J5: 97.4 | K5: 66.9 | L5: 144 | M5: 82.1 | N5: 4.7 | O5: 78.7 | P5: ='Raw Data'!R4/'Raw Data'!P4*100 -> 78.15534 | Q5: 0 | R5: 72.8 | S5: 1.3 | T5: ='Raw Data'!Z4/'Target Population'!M5*100 -> 90.33101 | U5: ='Raw Data'!AA4/'Target Population'!N5*100 -> 83.234714 | V5: ='Raw Data'!AH4/'Target Population'!L5*100 -> 69.734789 | W5: ='Raw Data'!AI4/'Raw Data'!AH4*100 -> 91.275168 | X5: ='Raw Data'!AN4/'Target Population'!L5*1000 -> 1153.6661 | Y5: ='Raw Data'!AO4/'Target Population'!L5*1000 -> 204.36817 | Z5: ='Raw Data'!AO4/('Raw Data'!AJ4+'Raw Data'!AK4+'Raw Data'!AL4)*100 -> 27.754237 | AA5: =('Raw Data'!AP4+'Raw Data'!AQ4+'Raw Data'!AR4)/'Raw Data'!AO4*100 -> 103.81679 | AB5: 76.5 | AC5: 35.7 | AD5: 39.4 | AE5: 31.8 | AF5: 14.4 | AG5: ='Raw Data'!BC4+'Raw Data'!BD4+'Raw Data'!BE4+'Raw Data'!BF4+'Raw Data'!BG4+'Raw Data'!BH4 -> 0 | AH5: ='Raw Data'!BQ4 -> 5 | AI5: ='Raw Data'!BI4+'Raw Data'!BJ4+'Raw Data'!BK4+'Raw Data'!BL4 -> 0 | AJ5: =('Raw Data'!BR4+'Raw Data'!BS4+'Raw Data'!BT4+'Raw Data'!BU4+'Raw Data'!BV4)/'Target Population'!Q5*100 -> 28.99475 | AK5: =SUM('Raw Data'!BW4:BY4)/'Target Population'!G5*100 -> 0 | AL5: ='Raw Data'!BZ4 -> 111 | AM5: ='Raw Data'!CA4/('Raw Data'!BZ4*12)*100 -> 59.234234 | AN5: ='Raw Data'!CC4/('Raw Data'!CB4*12)*100 -> 91.694352 | AO5: 10 | AP5: ='Raw Data'!CD4 -> 0 | AQ5: ='Raw Data'!CE4 -> 0 | AR5: 3 | AS5: 0 | AT5: 0 | AU5: ='Top Ten Disease (OPD)'!HF5 -> 0 | AV5: ='Top Ten Disease (OPD)'!HD5 -> 0 | AW5: ='Raw Data'!CG4 -> 3 | AX5: ='Raw Data'!CO4+'Raw Data'!CP4 -> 0 | AY5: 0 | AZ5: ='Raw Data'!CR4+'Raw Data'!CS4 -> 11174 | BA5: =AZ5/'Target Population'!F5*100 -> 91.31323 | BB5: ='Raw Data'!CS4/'Raw Data'!CR4*100 -> 93.422191 | BC5: 97.2
A6: 10102 | B6: Rural Municipality | C6: Province 1 | D6: Taplejung | E6: Mikwakhola Rural Municipality | F6: 86.8 | G6: 94.6 | H6: 93.6 | I6: 95.1 | J6: 91.7 | K6: 57.3 | L6: 71.8 | M6: 71.6 | N6: 1 | O6: 42.2 | P6: ='Raw Data'!R5/'Raw Data'!P5*100 -> 89.336158 | Q6: 2.7 | R6: 61.6 | S6: 2.6 | T6: ='Raw Data'!Z5/'Target Population'!M6*100 -> 78.736842 | U6: ='Raw Data'!AA5/'Target Population'!N6*100 -> 79.599057 | V6: ='Raw Data'!AH5/'Target Population'!L6*100 -> 71.863118 | W6: ='Raw Data'!AI5/'Raw Data'!AH5*100 -> 90.343915 | X6: ='Raw Data'!AN5/'Target Population'!L6*1000 -> 890.68441 | Y6: ='Raw Data'!AO5/'Target Population'!L6*1000 -> 48.479087 | Z6: ='Raw Data'!AO5/('Raw Data'!AJ5+'Raw Data'!AK5+'Raw Data'!AL5)*100 -> 14.127424 | AA6: =('Raw Data'!AP5+'Raw Data'!AQ5+'Raw Data'!AR5)/'Raw Data'!AO5*100 -> 96.078431 | AB6: 76.8 | AC6: 27 | AD6: 60.2 | AE6: 17.5 | AF6: 19.4 | AG6: ='Raw Data'!BC5+'Raw Data'!BD5+'Raw Data'!BE5+'Raw Data'!BF5+'Raw Data'!BG5+'Raw Data'!BH5 -> 2 | AH6: ='Raw Data'!BQ5 -> 5 | AI6: ='Raw Data'!BI5+'Raw Data'!BJ5+'Raw Data'!BK5+'Raw Data'!BL5 -> 0 | AJ6: =('Raw Data'!BR5+'Raw Data'!BS5+'Raw Data'!BT5+'Raw Data'!BU5+'Raw Data'!BV5)/'Target Population'!Q6*100 -> 16.214487 | AK6: =SUM('Raw Data'!BW5:BY5)/'Target Population'!G6*100 -> 0 | AL6: ='Raw Data'!BZ5 -> 62.833333 | AM6: ='Raw Data'!CA5/('Raw Data'!BZ5*12)*100 -> 22.811671 | AN6: ='Raw Data'!CC5/('Raw Data'!CB5*12)*100 -> 79.768786 | AO6: 8.4 | AP6: ='Raw Data'!CD5 -> 0 | AQ6: ='Raw Data'!CE5 -> 0 | AR6: 3 | AT6: 0 | AU6: ='Top Ten Disease (OPD)'!HF6 -> 0 | AV6: ='Top Ten Disease (OPD)'!HD6 -> 0 | AW6: ='Raw Data'!CG5 -> 7 | AX6: ='Raw Data'!CO5+'Raw Data'!CP5 -> 0 | AY6: 0 | AZ6: ='Raw Data'!CR5+'Raw Data'!CS5 -> 5472 | BA6: =AZ6/'Target Population'!F6*100 -> 58.813414 | BB6: ='Raw Data'!CS5/'Raw Data'!CR5*100 -> 92.269852 | BC6: 90
A7: 10103 | B7: Rural Municipality | C7: Province 1 | D7: Taplejung | E7: Meringden Rural Municipality | F7: 84.3 | G7: 73.9 | H7: 71.9 | I7: 75.6 | J7: 69.9 | K7: 59.7 | L7: 70 | M7: 73.6 | N7: 2.7 | O7: 55.7 | P7: ='Raw Data'!R6/'Raw Data'!P6*100 -> 95.081967 | Q7: 5.2 | R7: 51.2 | S7: 0.3 | T7: ='Raw Data'!Z6/'Target Population'!M7*100 -> 92.517537 | U7: ='Raw Data'!AA6/'Target Population'!N7*100 -> 92.586055 | V7: ='Raw Data'!AH6/'Target Population'!L7*100 -> 46.997207 | W7: ='Raw Data'!AI6/'Raw Data'!AH6*100 -> 100 | X7: ='Raw Data'!AN6/'Target Population'!L7*1000 -> 781.42458 | Y7: ='Raw Data'!AO6/'Target Population'!L7*1000 -> 84.497207 | Z7: ='Raw Data'!AO6/('Raw Data'!AJ6+'Raw Data'!AK6+'Raw Data'!AL6)*100 -> 19.267516 | AA7: =('Raw Data'!AP6+'Raw Data'!AQ6+'Raw Data'!AR6)/'Raw Data'!AO6*100 -> 90.909091 | AB7: 79.3 | AC7: 21.7 | AD7: 22.7 | AE7: 26.2 | AF7: 6.1 | AG7: ='Raw Data'!BC6+'Raw Data'!BD6+'Raw Data'!BE6+'Raw Data'!BF6+'Raw Data'!BG6+'Raw Data'!BH6 -> 0 | AH7: ='Raw Data'!BQ6 -> 4 | AI7: ='Raw Data'!BI6+'Raw Data'!BJ6+'Raw Data'!BK6+'Raw Data'!BL6 -> 20 | AJ7: =('Raw Data'!BR6+'Raw Data'!BS6+'Raw Data'!BT6+'Raw Data'!BU6+'Raw Data'!BV6)/'Target Population'!Q7*100 -> 26.324581 | AK7: =SUM('Raw Data'!BW6:BY6)/'Target Population'!G7*100 -> 0 | AL7: ='Raw Data'!BZ6 -> 108.33333 | AM7: ='Raw Data'!CA6/('Raw Data'!BZ6*12)*100 -> 52 | AN7: ='Raw Data'!CC6/('Raw Data'!CB6*12)*100 -> 96.208531 | AO7: 9.9 | AP7: ='Raw Data'!CD6 -> 0 | AQ7: ='Raw Data'!CE6 -> 0 | AR7: 6 | AS7: 0 | AT7: 0 | AU7: ='Top Ten Disease (OPD)'!HF7 -> 0 | AV7: ='Top Ten Disease (OPD)'!HD7 -> 0 | AW7: ='Raw Data'!CG6 -> 0 | AX7: ='Raw Data'!CO6+'Raw Data'!CP6 -> 0 | AY7: 0 | AZ7: ='Raw Data'!CR6+'Raw Data'!CS6 -> 8974 | BA7: =AZ7/'Target Population'!F7*100 -> 65.709892 | BB7: ='Raw Data'!CS6/'Raw Data'!CR6*100 -> 98.891844 | BC7: 83.3
